Workbook

Sheet Regression
A1: SUMMARY OUTPUT
A3: Regression Statistics
A4: Multiple R | B4: 0.7131788
A5: R Square | B5: 0.508624
A6: Adjusted R Square | B6: 0.50360995
A7: Standard Error | B7: 42.59996
A8: Observations | B8: 100
A10: ANOVA
B11: df | C11: SS | D11: MS | E11: F | F11: Significance F
A12: Regression | B12: 1 | C12: 184088.8 | D12: 184088.8 | E12: 101.43994 | F12: 8.4567412e-17
A13: Residual | B13: 98 | C13: 177846.15 | D13: 1814.7566
A14: Total | B14: 99 | C14: 361934.94
B16: Coefficients | C16: Standard Error | D16: t Stat | E16: P-value | F16: Lower 95% | G16: Upper 95% | H16: Lower 95.0% | I16: Upper 95.0%
A17: Intercept | B17: 847.07192 | C17: 8.7907543 | D17: 96.359412 | E17: 6.7995111e-99 | F17: 829.62695 | G17: 864.51688 | H17: 829.62695 | I17: 864.51688
A18: Meal_share | B18: -154.8951 | C18: 15.37918 | D18: -10.07174 | E18: 8.4567412e-17 | F18: -185.41458 | G18: -124.37562 | H18: -185.41458 | I18: -124.37562
A22: RESIDUAL OUTPUT
A24: Observation | B24: Predicted Test_score | C24: Residuals
A25: 1 | B25: 834.2813 | C25: 22.276699
A26: 2 | B26: 731.722 | C26: 17.695996
A27: 3 | B27: 823.87684 | C27: 79.290157
A28: 4 | B28: 718.34464 | C28: 52.051356
A29: 5 | B29: 722.80376 | C29: -30.182764
A30: 6 | B30: 773.3403 | C30: -37.254303
A31: 7 | B31: 783.74492 | C31: 36.180083
A32: 8 | B32: 762.93569 | C32: 73.44031
A33: 9 | B33: 788.20388 | C33: 27.765118
A34: 10 | B34: 825.36306 | C34: -16.389061
A35: 11 | B35: 777.79942 | C35: -21.169423
A36: 12 | B36: 724.29014 | C36: 120.54886
... A124: 100 | B124: 806.04036 | C124: -6.4573624

Sheet Paso_a_paso
A1: OLS BY HAND: 100 SIMULATED SCHOOLS
A2: Yellow cells are results used in the lecture. Formulas update when Data changes.
A3: Step | B3: Concept | C3: Value | D3: Excel formula / explanation
A4: 1 | B4: Sample size n | C4: =COUNT(Data!A2:A101) -> 100 | D4: =COUNT(Data!A2:A101)
A5: 2 | B5: Mean X (X-bar) | C5: =AVERAGE(Data!A2:A101) -> 0.5 | D5: =AVERAGE(Data!A2:A101)
A6: 3 | B6: Mean Y (Y-bar) | C6: =AVERAGE(Data!B2:B101) -> 769.62437 | D6: =AVERAGE(Data!B2:B101)
A7: 4 | B7: Sum (Xi - X-bar) | C7: =SUM(D43:D142) -> 0 | D7: =SUM(D43:D142)
A8: 5 | B8: Sum (Yi - Y-bar) | C8: =SUM(E43:E142) -> 3.4106051e-13 | D8: =SUM(E43:E142)
A9: 6 | B9: TSS_X | C9: =SUM(F43:F142) -> 7.6727671 | D9: =SUM(F43:F142)
A10: 7 | B10: Cross-product sum | C10: =SUM(H43:H142) -> -1188.474 | D10: =SUM(H43:H142)
A11: 8 | B11: Sample variance s_X^2 | C11: =C9/(C4-1) -> 0.077502697 | D11: =C9/(C4-1)
A12: 9 | B12: Sample covariance s_XY | C12: =C10/(C4-1) -> -12.004788 | D12: =C10/(C4-1)
A13: 10 | B13: Slope b1-hat | C13: =C10/C9 -> -154.8951 | D13: =C10/C9
A14: 11 | B14: Intercept b0-hat | C14: =C6-C13*C5 -> 847.07192 | D14: =C6-C13*C5
A15: 12 | B15: SSR (sum residual^2) | C15: =SUM(K43:K142) -> 177846.15 | D15: =SUM(K43:K142)
A16: 13 | B16: TSS_Y | C16: =SUM(G43:G142) -> 361934.94 | D16: =SUM(G43:G142)
A17: 14 | B17: ESS (explained SS) | C17: =SUM(L43:L142) -> 184088.8 | D17: =SUM(L43:L142)
A18: 15 | B18: R Square | C18: =1-C15/C16 -> 0.508624 | D18: =1-C15/C16
A19: 16 | B19: Residual degrees of freedom | C19: =C4-2 -> 98 | D19: =C4-2
A20: 17 | B20: SER (Excel Standard Error) | C20: =SQRT(C15/C19) -> 42.59996 | D20: =SQRT(C15/C19)
A21: 18 | B21: RMSE (denominator n) | C21: =SQRT(C15/C4) -> 42.171809 | D21: =SQRT(C15/C4)
A22: 19 | B22: SE of slope b1-hat | C22: =C20/SQRT(C9) -> 15.37918 | D22: =C20/SQRT(C9)
A23: 20 | B23: SE of intercept b0-hat | C23: =C20*SQRT(1/C4+C5^2/C9) -> 8.7907543 | D23: =C20*SQRT(1/C4+C5^2/C9)
A24: 21 | B24: t statistic: H0 b1 = 0 | C24: =C13/C22 -> -10.07174 | D24: =C13/C22
A25: 22 | B25: t statistic: H0 b0 = 0 | C25: =C14/C23 -> 96.359412 | D25: =C14/C23
A26: 23 | B26: Two-sided p-value: b1 | C26: =_xlfn.T.DIST.2T(ABS(C24),C19) -> 8.4567412e-17 | D26: =T.DIST.2T(ABS(C24),C19)
A27: 24 | B27: Two-sided p-value: b0 | C27: =_xlfn.T.DIST.2T(ABS(C25),C19) -> 6.7995111e-99 | D27: =T.DIST.2T(ABS(C25),C19)
A28: 25 | B28: 95% critical t value | C28: =_xlfn.T.INV.2T(0.05,C19) -> 1.9844675 | D28: =T.INV.2T(0.05,C19)
A29: 26 | B29: Slope: lower 95% | C29: =C13-C28*C22 -> -185.41458 | D29: =C13-C28*C22
A30: 27 | B30: Slope: upper 95% | C30: =C13+C28*C22 -> -124.37562 | D30: =C13+C28*C22
A31: 28 | B31: Intercept: lower 95% | C31: =C14-C28*C23 -> 829.62695 | D31: =C14-C28*C23
A32: 29 | B32: Intercept: upper 95% | C32: =C14+C28*C23 -> 864.51688 | D32: =C14+C28*C23
A33: 30 | B33: Adjusted R Square | C33: =1-(1-C18)*(C4-1)/C19 -> 0.50360995 | D33: =1-(1-C18)*(C4-1)/C19
A34: 31 | B34: Check: sum residuals | C34: =SUM(J43:J142) -> 3.4106051e-13 | D34: =SUM(J43:J142)
A35: 32 | B35: Check: sum Xi * residual | C35: =SUM(M43:M142) -> 5.1736393e-14 | D35: =SUM(M43:M142)
A36: 33 | B36: Check: R2 minus ToolPak | C36: =C18-Regression!B5 -> 0 | D36: =C18-Regression!B5
A37: 34 | B37: Check: b1 minus ToolPak | C37: =C13-Regression!B18 -> 0 | D37: =C13-Regression!B18
A38: Checks should be zero up to rounding. ToolPak output is a snapshot: rerun after changing Data.
A39: SEs assume homoskedasticity. Exact t tests also assume conditionally normal errors.
A40: Read each row below: centre X and Y, multiply, fit Y, then square the residual.
...

Sheet Data
A1: Meal_share | B1: Test_score | C1: School_ID | E1: SIMULATED DATA: 100 schools
A2: 0.082576 | B2: 856.558 | C2: 1 | E2: Teaching example inspired by Lecture 4. These are not actual school records.
A3: 0.744697 | B3: 749.418 | C3: 2 | E3: X is a share from 0 to 1. A rise of 0.10 means 10 percentage points.
A4: 0.149747 | B4: 903.167 | C4: 3 | E4: Y is the school average test score, in points.
A5: 0.831061 | B5: 770.396 | C5: 4 | E5: Fixed simulated values. Rerun Data Analysis > Regression after changes.
A6: 0.802273 | B6: 692.621 | C6: 5
A7: 0.47601 | B7: 736.086 | C7: 6
A8: 0.408838 | B8: 819.925 | C8: 7
A9: 0.543182 | B9: 836.376 | C9: 8
A10: 0.380051 | B10: 815.969 | C10: 9
A11: 0.140152 | B11: 808.974 | C11: 10
A12: 0.447222 | B12: 756.63 | C12: 11
A13: 0.792677 | B13: 844.839 | C13: 12
A14: 0.840657 | B14: 679.514 | C14: 13
A15: 0.581566 | B15: 844.019 | C15: 14
A16: 0.130556 | B16: 819.897 | C16: 15
A17: 0.706313 | B17: 753.718 | C17: 16
... A101: 0.264899 | B101: 799.583 | C101: 100
